Workbook

Sheet Instrucciones
A1: KIT DE CARGA — Catálogo CR (223 versões) para QA / UAT · gerado 14/07
A3: PRÉ-REQUISITO (uma vez por org): deploy do deploy_precios_catalogo.zip via Workbench (Check Only antes) = 7 campos de precio + history + PS_Precios_Catalogo. Atribuir o PS ao seu usuário.
A5: PASSO 1 — Parametros: na org destino, rodar e colar os Ids na aba Parametros:
A6: Q1: SELECT Id, Name, IsStandard FROM Pricebook2 -> Id do Standard em Parametros!B2
A7: Se nao existir C101: importar a aba 0_Pricebooks (Inspector Data Import -> Pricebook2 -> Insert), re-rodar Q1 -> Id do C101 em Parametros!B3
A8: Q2: SELECT Id, Name FROM BusinessBrand WHERE Name IN ('Hyundai','Chevrolet','Isuzu','Cadillac') -> colar cada Id em Parametros!B4:B7 (faltou marca? criar na aba Business Brands antes)
A10: PASSO 2 — Produtos: aba 1_Product2 -> conferir que a coluna E preencheu -> selecionar A1:F218 -> copiar -> Inspector Data Import -> Object Product2 -> INSERT -> Run (esperado 217 Succeeded)
A12: PASSO 3 — Mapa: rodar SELECT ProductCode, Id FROM Product2 WHERE IsActive = true -> Copy (Excel format) -> colar em MapaProductos!A1
A14: PASSO 4 — Preço de lista: aba 2_PBE_Standard -> selecionar A1:E218 -> copiar -> Inspector -> PricebookEntry -> INSERT (217). SEMPRE antes do C101.
A16: PASSO 5 — Precios: aba 3_PBE_C101 -> selecionar A1:K218 -> copiar -> Inspector -> PricebookEntry -> INSERT (217)
A18: PROVA: SELECT Pricebook2.Name, COUNT(Id) FROM PricebookEntry GROUP BY Pricebook2.Name -> 217/217. Spot-check: ProductCode 0YS4D661V D D394 2025 no C101 = 31400/26900/21700/1600/3000
A20: NOTAS: moeda = a padrão da org (sem coluna CurrencyIsoCode; se a org destino tiver USD ativa e a decisão for USD, me pedir a versão com moeda). Não copiar as colunas de referência (G no 2_PBE, M no 3_PBE) — ficam fora do intervalo indicado.

Sheet Parametros
A1: Parámetro | B1: Id (colar da ORG DESTINO)
A2: Standard Price Book
A3: C101 - Vehiculos y Motos (CR)
A4: Hyundai
A5: Chevrolet
A6: Isuzu
A7: Cadillac

Sheet 0_Pricebooks
A1: Name | B1: IsActive | C1: Description
A2: C101 - Vehiculos y Motos (CR) | B2: true | C2: Lista de precios sociedad C101 Costa Rica
A3: C105 - Motos (CR) | B3: true | C3: Lista de precios sociedad C105 Active Motors CR (opcional nesta fase)

Sheet 1_Product2
A1: Name | B1: ProductCode | C1: Family | D1: MakeName | E1: BusinessBrandId | F1: IsActive
A2: Accent Sedan Limited 1.500 cc Gas T/A 2WD | B2: 0YS4D661V D D394 2025 | C2: Autos | D2: Hyundai | E2: =VLOOKUP(D2,Parametros!$A$4:$B$7,2,FALSE) | F2: true
A3: Accent Sedan Sport Plus 1.500 cc Gas T/A 2WD | B3: 0YS4D661V D D571 2025 | C3: Autos | D3: Hyundai | E3: =VLOOKUP(D3,Parametros!$A$4:$B$7,2,FALSE) | F3: true
A4: Accent Sedan Limited Plus 1.500 cc Gas T/A 2WD | B4: 0YS4D661V D D572 2025 | C4: Autos | D4: Hyundai | E4: =VLOOKUP(D4,Parametros!$A$4:$B$7,2,FALSE) | F4: true
A5: Accent Sedan Fun 1.500 cc Gas T/A 2WD | B5: 0YS4D661V D D720 2026 | C5: Autos | D5: Hyundai | E5: =VLOOKUP(D5,Parametros!$A$4:$B$7,2,FALSE) | F5: true
A6: Accent Sedan Limited Plus 1.500 cc Gas T/A 2WD | B6: 0YS4D661V D D743 2026 | C6: Autos | D6: Hyundai | E6: =VLOOKUP(D6,Parametros!$A$4:$B$7,2,FALSE) | F6: true
A7: COLORADO LTZ D/C 2.8L 4X4 T/A DSL | B7: 12L43-D 2025 | C7: Autos | D7: Chevrolet | E7: =VLOOKUP(D7,Parametros!$A$4:$B$7,2,FALSE) | F7: true
A8: COLORADO LTZ D/C 2.8L 4X4 T/A DSL | B8: 12L43-D 2026 | C8: Autos | D8: Chevrolet | E8: =VLOOKUP(D8,Parametros!$A$4:$B$7,2,FALSE) | F8: true
A9: COLORADO Z71 D/C 2.8L 4X4 T/A DSL | B9: 12L43-E 2026 | C9: Autos | D9: Chevrolet | E9: =VLOOKUP(D9,Parametros!$A$4:$B$7,2,FALSE) | F9: true
A10: COLORADO HC D/C 2.8L 4X4 T/A DSL | B10: 12L43-G 2025 | C10: Autos | D10: Chevrolet | E10: =VLOOKUP(D10,Parametros!$A$4:$B$7,2,FALSE) | F10: true
A11: COLORADO HC D/C 2.8L 4X4 T/A DSL | B11: 12L43-G 2026 | C11: Autos | D11: Chevrolet | E11: =VLOOKUP(D11,Parametros!$A$4:$B$7,2,FALSE) | F11: true
A12: TRAILBLAZER HC 2.8L 4X4 T/A DSL | B12: 12S26-G 2025 | C12: Autos | D12: Chevrolet | E12: =VLOOKUP(D12,Parametros!$A$4:$B$7,2,FALSE) | F12: true
A13: TRAILBLAZER HC 2.8L 4X4 T/A DSL | B13: 12S26-G 2026 | C13: Autos | D13: Chevrolet | E13: =VLOOKUP(D13,Parametros!$A$4:$B$7,2,FALSE) | F13: true
... A218: MU-X 4X4 3.0L T/A TELA (UJCL502) PREMIUM | B218: UJCL502 2026 | C218: Autos | D218: Isuzu | E218: =VLOOKUP(D218,Parametros!$A$4:$B$7,2,FALSE) | F218: true

Sheet MapaProductos
A1: << colar aqui o resultado de: SELECT ProductCode, Id FROM Product2 WHERE IsActive = true (Copy Excel format, com cabecalho) >>

Sheet 2_PBE_Standard
A1: Product2Id | B1: Pricebook2Id | C1: UnitPrice | D1: IsActive | E1: UseStandardPrice | G1: ProductCode (ref - NAO copiar)
A2: =VLOOKUP(G2,MapaProductos!$A:$B,2,FALSE) | B2: =Parametros!$B$2 | C2: 31400 | D2: true | E2: false | G2: 0YS4D661V D D394 2025
A3: =VLOOKUP(G3,MapaProductos!$A:$B,2,FALSE) | B3: =Parametros!$B$2 | C3: 30400 | D3: true | E3: false | G3: 0YS4D661V D D571 2025
A4: =VLOOKUP(G4,MapaProductos!$A:$B,2,FALSE) | B4: =Parametros!$B$2 | C4: 33400 | D4: true | E4: false | G4: 0YS4D661V D D572 2025
A5: =VLOOKUP(G5,MapaProductos!$A:$B,2,FALSE) | B5: =Parametros!$B$2 | C5: 30400 | D5: true | E5: false | G5: 0YS4D661V D D720 2026
A6: =VLOOKUP(G6,MapaProductos!$A:$B,2,FALSE) | B6: =Parametros!$B$2 | C6: 34400 | D6: true | E6: false | G6: 0YS4D661V D D743 2026
A7: =VLOOKUP(G7,MapaProductos!$A:$B,2,FALSE) | B7: =Parametros!$B$2 | C7: 62900 | D7: true | E7: false | G7: 12L43-D 2025
A8: =VLOOKUP(G8,MapaProductos!$A:$B,2,FALSE) | B8: =Parametros!$B$2 | C8: 63500 | D8: true | E8: false | G8: 12L43-D 2026
A9: =VLOOKUP(G9,MapaProductos!$A:$B,2,FALSE) | B9: =Parametros!$B$2 | C9: 59900 | D9: true | E9: false | G9: 12L43-E 2026
A10: =VLOOKUP(G10,MapaProductos!$A:$B,2,FALSE) | B10: =Parametros!$B$2 | C10: 65900 | D10: true | E10: false | G10: 12L43-G 2025
A11: =VLOOKUP(G11,MapaProductos!$A:$B,2,FALSE) | B11: =Parametros!$B$2 | C11: 65900 | D11: true | E11: false | G11: 12L43-G 2026
A12: =VLOOKUP(G12,MapaProductos!$A:$B,2,FALSE) | B12: =Parametros!$B$2 | C12: 67900 | D12: true | E12: false | G12: 12S26-G 2025
A13: =VLOOKUP(G13,MapaProductos!$A:$B,2,FALSE) | B13: =Parametros!$B$2 | C13: 68900 | D13: true | E13: false | G13: 12S26-G 2026
... A218: =VLOOKUP(G218,MapaProductos!$A:$B,2,FALSE) | B218: =Parametros!$B$2 | C218: 63900 | D218: true | E218: false | G218: UJCL502 2026

Sheet 3_PBE_C101
A1: Product2Id | B1: Pricebook2Id | C1: UnitPrice | D1: IsActive | E1: UseStandardPrice | F1: PrecioMinimoAsesor__c | G1: PrecioExonerado__c | H1: PrecioExoneradoMinimo__c | I1: Gastos__c | J1: MontoCashback__c | K1: AplicaCashback__c | M1: ProductCode (ref - NAO copiar)
A2: =VLOOKUP(M2,MapaProductos!$A:$B,2,FALSE) | B2: =Parametros!$B$3 | C2: 31400 | D2: true | E2: false | F2: 26900 | G2: 21700 | H2: 17900 | I2: 1600 | J2: 3000 | K2: false | M2: 0YS4D661V D D394 2025
A3: =VLOOKUP(M3,MapaProductos!$A:$B,2,FALSE) | B3: =Parametros!$B$3 | C3: 30400 | D3: true | E3: false | F3: 24400 | G3: 21300 | H3: 16800 | I3: 1600 | J3: 4500 | K3: false | M3: 0YS4D661V D D571 2025
A4: =VLOOKUP(M4,MapaProductos!$A:$B,2,FALSE) | B4: =Parametros!$B$3 | C4: 33400 | D4: true | E4: false | F4: 28900 | G4: 23100 | H4: 19200 | I4: 1600 | J4: 3000 | K4: false | M4: 0YS4D661V D D572 2025
A5: =VLOOKUP(M5,MapaProductos!$A:$B,2,FALSE) | B5: =Parametros!$B$3 | C5: 30400 | D5: true | E5: false | F5: 27400 | G5: 20600 | H5: 17500 | I5: 2000 | J5: 3000 | K5: false | M5: 0YS4D661V D D720 2026
A6: =VLOOKUP(M6,MapaProductos!$A:$B,2,FALSE) | B6: =Parametros!$B$3 | C6: 34400 | D6: true | E6: false | F6: 30900 | G6: 23700 | H6: 20100 | I6: 1600 | J6: 3000 | K6: false | M6: 0YS4D661V D D743 2026
A7: =VLOOKUP(M7,MapaProductos!$A:$B,2,FALSE) | B7: =Parametros!$B$3 | C7: 62900 | D7: true | E7: false | F7: 54700 | G7: 41337.5 | H7: 62400 | I7: 1900 | K7: false | M7: 12L43-D 2025
A8: =VLOOKUP(M8,MapaProductos!$A:$B,2,FALSE) | B8: =Parametros!$B$3 | C8: 63500 | D8: true | E8: false | F8: 58400 | G8: 41688.75 | H8: 63000 | I8: 1900 | K8: false | M8: 12L43-D 2026
A9: =VLOOKUP(M9,MapaProductos!$A:$B,2,FALSE) | B9: =Parametros!$B$3 | C9: 59900 | D9: true | E9: false | F9: 54800 | G9: 39626.25 | H9: 59400 | I9: 1800 | K9: false | M9: 12L43-E 2026
A10: =VLOOKUP(M10,MapaProductos!$A:$B,2,FALSE) | B10: =Parametros!$B$3 | C10: 65900 | D10: true | E10: false | F10: 57700 | G10: 43478.75 | H10: 65400 | I10: 2100 | K10: false | M10: 12L43-G 2025
A11: =VLOOKUP(M11,MapaProductos!$A:$B,2,FALSE) | B11: =Parametros!$B$3 | C11: 65900 | D11: true | E11: false | F11: 60800 | G11: 43848.75 | H11: 65400 | I11: 2100 | K11: false | M11: 12L43-G 2026
A12: =VLOOKUP(M12,MapaProductos!$A:$B,2,FALSE) | B12: =Parametros!$B$3 | C12: 67900 | D12: true | E12: false | F12: 59800 | G12: 43805 | H12: 67400 | I12: 2100 | K12: false | M12: 12S26-G 2025
A13: =VLOOKUP(M13,MapaProductos!$A:$B,2,FALSE) | B13: =Parametros!$B$3 | C13: 68900 | D13: true | E13: false | F13: 64800 | G13: 44602.5 | H13: 68400 | I13: 2100 | K13: false | M13: 12S26-G 2026
A14: =VLOOKUP(M14,MapaProductos!$A:$B,2,FALSE) | B14: =Parametros!$B$3 | C14: 27900 | D14: true | E14: false | F14: 27500 | G14: 27900 | H14: 25800 | I14: 800 | K14: false | M14: 1E426-A 2026
A15: =VLOOKUP(M15,MapaProductos!$A:$B,2,FALSE) | B15: =Parametros!$B$3 | C15: 27900 | D15: true | E15: false | F15: 27500 | G15: 27900 | H15: 25800 | I15: 800 | K15: false | M15: 1E426-B 2026
A16: =VLOOKUP(M16,MapaProductos!$A:$B,2,FALSE) | B16: =Parametros!$B$3 | C16: 28900 | D16: true | E16: false | F16: 27100 | G16: 20990 | H16: 28900 | I16: 900 | K16: false | M16: 1EH76-C 2026
A17: =VLOOKUP(M17,MapaProductos!$A:$B,2,FALSE) | B17: =Parametros!$B$3 | C17: 33900 | D17: true | E17: false | F17: 28800 | G17: 21027.5 | H17: 33400 | I17: 900 | K17: false | M17: 1EH76-R 2025
A18: =VLOOKUP(M18,MapaProductos!$A:$B,2,FALSE) | B18: =Parametros!$B$3 | C18: 35500 | D18: true | E18: false | F18: 28900 | G18: 22555 | H18: 35000 | I18: 1000 | K18: false | M18: 1EJ76-D 2025
A19: =VLOOKUP(M19,MapaProductos!$A:$B,2,FALSE) | B19: =Parametros!$B$3 | C19: 32500 | D19: true | E19: false | F19: 31000 | G19: 22768 | H19: 32500 | I19: 1000 | K19: false | M19: 1EJ76-D 2026
A20: =VLOOKUP(M20,MapaProductos!$A:$B,2,FALSE) | B20: =Parametros!$B$3 | C20: 38400 | D20: true | E20: false | F20: 31830 | G20: 26970 | H20: 24070 | I20: 1800 | J20: 4000 | K20: false | M20: 1EW52J61V D D466 2025
A21: =VLOOKUP(M21,MapaProductos!$A:$B,2,FALSE) | B21: =Parametros!$B$3 | C21: 39400 | D21: true | E21: false | F21: 32830 | G21: 27570 | H21: 23670 | I21: 1800 | J21: 5000 | K21: false | M21: 1EW52J61V D D579 2025
A22: =VLOOKUP(M22,MapaProductos!$A:$B,2,FALSE) | B22: =Parametros!$B$3 | C22: 40400 | D22: true | E22: false | F22: 33830 | G22: 28270 | H22: 23870 | I22: 1800 | J22: 5000 | K22: false | M22: 1EW52J61V D D579 2026
A23: =VLOOKUP(M23,MapaProductos!$A:$B,2,FALSE) | B23: =Parametros!$B$3 | C23: 35400 | D23: true | E23: false | F23: 31830 | G23: 24370 | H23: 21270 | I23: 1800 | J23: 3000 | K23: false | M23: 1EW52J61V D D591 2025
A24: =VLOOKUP(M24,MapaProductos!$A:$B,2,FALSE) | B24: =Parametros!$B$3 | C24: 45600 | D24: true | E24: false | F24: 42030 | G24: 31370 | H24: 27870 | I24: 2000 | J24: 3000 | K24: false | M24: 1EW5D5G1K D D467 2025
A25: =VLOOKUP(M25,MapaProductos!$A:$B,2,FALSE) | B25: =Parametros!$B$3 | C25: 42500 | D25: true | E25: false | F25: 34930 | G25: 29670 | H25: 27770 | I25: 1900 | J25: 5000 | K25: false | M25: 1EW5D5G1K D D468. 2025
A26: =VLOOKUP(M26,MapaProductos!$A:$B,2,FALSE) | B26: =Parametros!$B$3 | C26: 48600 | D26: true | E26: false | F26: 45030 | G26: 33670 | H26: 30170 | I26: 2000 | J26: 3000 | K26: false | M26: 1EW5D5G1K D D690. 2026
A27: =VLOOKUP(M27,MapaProductos!$A:$B,2,FALSE) | B27: =Parametros!$B$3 | C27: 43500 | D27: true | E27: false | F27: 35930 | G27: 30470 | H27: 28170 | I27: 1900 | J27: 5000 | K27: false | M27: 1EW5D5G1K D D691. 2025
A28: =VLOOKUP(M28,MapaProductos!$A:$B,2,FALSE) | B28: =Parametros!$B$3 | C28: 57200 | D28: true | E28: false | F28: 41100 | G28: 57200 | H28: 41100 | I28: 2800 | J28: 16100 | K28: false | M28: 1FW5ZHZ7Z D D106 2024
A29: =VLOOKUP(M29,MapaProductos!$A:$B,2,FALSE) | B29: =Parametros!$B$3 | C29: 59100 | D29: true | E29: false | F29: 50100 | G29: 59100 | H29: 50100 | I29: 2800 | J29: 9000 | K29: false | M29: 1FW5ZHZ7Z D D123 2025
A30: =VLOOKUP(M30,MapaProductos!$A:$B,2,FALSE) | B30: =Parametros!$B$3 | C30: 48800 | D30: true | E30: false | F30: 37800 | G30: 48800 | H30: 38800 | I30: 2500 | J30: 10000 | K30: false | M30: 1FW5ZHZ7Z D D137 2025
A31: =VLOOKUP(M31,MapaProductos!$A:$B,2,FALSE) | B31: =Parametros!$B$3 | C31: 59100 | D31: true | E31: false | F31: 50100 | G31: 59100 | H31: 50100 | I31: 2800 | J31: 9000 | K31: false | M31: 1FW5ZHZ7Z D D202 2025
... A34: =VLOOKUP(M34,MapaProductos!$A:$B,2,FALSE) | B34: =Parametros!$B$3 | C34: 59100 | D34: true | E34: false | F34: 55100 | G34: 59100 | H34: 55100 | I34: 2600 | J34: 4000 | K34: false | M34: 1FW5ZHZ7Z D D259 2026
A35: =VLOOKUP(M35,MapaProductos!$A:$B,2,FALSE) | B35: =Parametros!$B$3 | C35: 22500 | D35: true | E35: false | F35: 18000 | G35: 17256.64 | H35: 19940.74 | I35: 600 | K35: false | M35: 1HH26AC-B 2025
A36: =VLOOKUP(M36,MapaProductos!$A:$B,2,FALSE) | B36: =Parametros!$B$3 | C36: 22500 | D36: true | E36: false | F36: 19400 | G36: 13355 | H36: 22000 | I36: 600 | K36: false | M36: 1HH26AC-B 2026
A37: =VLOOKUP(M37,MapaProductos!$A:$B,2,FALSE) | B37: =Parametros!$B$3 | C37: 84500 | D37: true | E37: false | F37: 79400 | G37: 55216.3 | H37: 84000 | I37: 2500 | K37: false | M37: 1LB56-D 2025
A38: =VLOOKUP(M38,MapaProductos!$A:$B,2,FALSE) | B38: =Parametros!$B$3 | C38: 86500 | D38: true | E38: false | F38: 83400 | G38: 56233 | H38: 86067 | I38: 2500 | K38: false | M38: 1LB56-D 2026
A39: =VLOOKUP(M39,MapaProductos!$A:$B,2,FALSE) | B39: =Parametros!$B$3 | C39: 67900 | D39: true | E39: false | F39: 54800 | G39: 48658.4 | H39: 67400 | I39: 1900 | K39: false | M39: 1NR26-D 2023
A40: =VLOOKUP(M40,MapaProductos!$A:$B,2,FALSE) | B40: =Parametros!$B$3 | C40: 74900 | D40: true | E40: false | F40: 59800 | G40: 49034.34 | H40: 74400 | I40: 2100 | K40: false | M40: 1NS26-G 2024
A41: =VLOOKUP(M41,MapaProductos!$A:$B,2,FALSE) | B41: =Parametros!$B$3 | C41: 37900 | D41: true | E41: false | F41: 31000 | G41: 22092.5 | H41: 37400 | I41: 1000 | K41: false | M41: 1SD26-B 2025
A42: =VLOOKUP(M42,MapaProductos!$A:$B,2,FALSE) | B42: =Parametros!$B$3 | C42: 37900 | D42: true | E42: false | F42: 33800 | G42: 20210 | H42: 37690 | I42: 1000 | K42: false | M42: 1SD26-B 2026
...
